Workbook

Sheet Instructions
A1: GEMS Compliance Marks Calculator
A2: Region / Zone level — OCRMS (off-site) & OCTMS (on-site) scoring per BCC:COMPLIANCE:118/993 (FY 2026-27)
A5: HOW TO USE
A6: 1. Export your OCRMS pivot report from your compliance system, unchanged — branches as rows, parameter codes as column headers, Grand Total row and column included (the same shape your system already produces).
A7: 2. Open the "OCRMS Data" tab. Select the WHOLE pivot table in your source (the "Row Labels" header cell through the Grand Total row and column) and paste it starting at cell A3 — nowhere else. Nothing needs reshaping; the sheet finds each parameter code and scores it automatically.
A8: 3. Open the "OCTMS Data" tab. This one takes the RAW system export directly — no pivoting needed. Select the whole export (every column, every row) from your system and paste it starting at cell A2.
A9: 4. Go to the "Calculator" tab and fill in the yellow input cells: total branches in the region, your grade, CERMO-Nxt %, penalty marks, Compliance Forum and AEOA status, and the Part C (ATR closure) counts.
A10: 5. The Grand Total (out of 10) updates automatically as you fill things in.
A12: CELL COLOUR KEY
A13: Blue text on pale yellow = type your own value here
A14: Black text = formula — do not overwrite
A15: Green text = a link pulling a value from another sheet
... A29: - This workbook has no macros and needs no internet connection — safe to use on a locked-down machine.

Sheet Calculator
A1: GEMS Compliance Marks Calculator
A2: Fill in the yellow cells. Everything else updates automatically.
A4: REGION SETUP
A6: Total branches in the Region | B6: 55
A7: Used as the denominator for Part B in both OCRMS and OCTMS.
A9: OCRMS — OFF-SITE (max 3)
A10: Part A — Parameter Risk Score (auto) | B10: ='OCRMS Data'!$B$313 -> 1
A11: Part B — Non-complied Branches (auto) | B11: ='OCRMS Data'!$B$318 -> 1
A12: Part C — initial non-complied instances | B12: 0
A13: Part C — closed & verified (month end) | B13: 0
A14: Part C — ATR Closure (auto) | B14: =IF(B12>0,MIN(1,MAX(0,ROUND(B13/B12,2))),0) -> 0
A15: OCRMS TOTAL (/3) | B15: =B10+B11+B14 -> 2
A17: OCTMS — ON-SITE (max 3)
A18: Part A — Parameter Risk Score (auto) | B18: ='OCTMS Data'!$B$2139 -> 1
A19: Part B — Non-complied Branches (auto) | B19: ='OCTMS Data'!$B$2144 -> 1
A20: Part C — initial non-complied instances | B20: 0
A21: Part C — closed & verified (60th day) | B21: 0
A22: Part C — ATR Closure (auto) | B22: =IF(B20>0,MIN(1,MAX(0,ROUND(B21/B20,2))),0) -> 0
A23: OCTMS TOTAL (/3) | B23: =B18+B19+B22 -> 2
A25: OTHER KRA ITEMS
A26: Grade | B26: Regional Head / DRM
A27: =IF(B26="Regional Head / DRM","OCRMS bucket = OCRMS+Cermo+AEOA (max 5). OCTMS bucket = OCTMS+Penalty+Forum (max 5).","OCRMS bucket = OCRMS+Cermo (max 4). OCTMS bucket = OCTMS+Penalty+Forum (max 6).") -> OCRMS bucket = OCRMS+Cermo+AEOA (max 5). OCTMS bucket = OCTMS+Penalty+Forum (max 5).
A29: CERMO-Nxt compliance level (%) | B29: 99.23
A30: Regulatory penalty marks — month 1 / 2 / 3 | B30: 1 | C30: 0.5 | D30: 1
A31: Compliance Forum Meeting held & reported? | B31: Yes
A32: AEOA Scheme data submitted to RCO? (Regional Head/DRM only) | B32: Yes
A34: Forum max (role-based) | B34: =IF(B26="Regional Head / DRM",1,2) -> 1
A35: AEOA applies? | B35: =IF(B26="Regional Head / DRM","Yes","No") -> Yes
A36: Cermo marks (0-1) | B36: =IF(B29>0,MIN(1,ROUND(B29/100,2)),0) -> 0.99
A37: Penalty marks (avg) | B37: =IFERROR(ROUND(AVERAGE(B30:D30),2),0) -> 0.83
A38: Forum marks | B38: =IF(B31="Yes",1,0)*B34 -> 1
A39: AEOA marks | B39: =IF(B35="Yes",IF(B32="Yes",1,0),0) -> 1
A41: TOTALS
A42: OCRMS bucket (Total + Cermo + AEOA) | B42: =B15+B36+B39 -> 3.99 | C42: =" / "&IF(B35="Yes",5,4) -> / 5
A43: OCTMS bucket (Total + Penalty + Forum) | B43: =B23+B37+B38 -> 3.83 | C43: =" / "&IF(B35="Yes",5,6) -> / 5
A45: GRAND TOTAL (out of 10) | B45: =ROUND(B42+B43,2) -> 7.82 | C45: / 10

Sheet OCRMS Risk Map
A1: Annexure-I — OCRMS parameter risk weights (reference only, do not edit)
A3: Parameter Code | B3: Risk Rating | C3: Weight
A4: PARAMETER-001 | B4: L | C4: 1
A5: PARAMETER-002 | B5: L | C5: 1
A6: PARAMETER-003 | B6: H | C6: 3
A7: PARAMETER-005 | B7: M | C7: 2
A8: PARAMETER-006 | B8: M | C8: 2
A9: PARAMETER-007 | B9: M | C9: 2
A10: PARAMETER-008 | B10: M | C10: 2
A11: PARAMETER-009 | B11: M | C11: 2
A12: PARAMETER-010 | B12: H | C12: 3
A13: PARAMETER-011 | B13: H | C13: 3
A14: PARAMETER-012 | B14: H | C14: 3
A15: PARAMETER-014 | B15: H | C15: 3
... A70: PARAMETER-084 | B70: H | C70: 3
A72: Total risk denominator (fixed, per circular): 139

Sheet OCTMS Risk Map
A1: Annexure-III — OCTMS parameter risk weights (reference only, do not edit)
A3: Parameter Code | B3: Risk Rating | C3: Weight
A4: A1 | B4: H | C4: 3
A5: A3 | B5: H | C5: 3
A6: A4 | B6: H | C6: 3
A7: A5 | B7: L | C7: 1
A8: A6 | B8: H | C8: 3
A9: A7 | B9: H | C9: 3
A10: A9 | B10: H | C10: 3
A11: A10 | B11: H | C11: 3
A12: A11 | B12: H | C12: 3
A13: A12 | B13: H | C13: 3
A14: A13 | B14: H | C14: 3
A15: A14 | B15: H | C15: 3
... A129: N4 | B129: H | C129: 3
A131: Total risk denominator (fixed, per circular): 302

Sheet OCRMS Data
A1: OCRMS Data — paste your WHOLE OCRMS pivot export here, starting at cell A3 | B1: =IF(B$3="",0,IFERROR(INDEX('OCRMS Risk Map'!$C:$C,MATCH(B$3,'OCRMS Risk Map'!$A:$A,0)),0)) -> 0 | C1: =IF(C$3="",0,IFERROR(INDEX('OCRMS Risk Map'!$C:$C,MATCH(C$3,'OCRMS Risk Map'!$A:$A,0)),0)) -> 0 | D1: =IF(D$3="",0,IFERROR(INDEX('OCRMS Risk Map'!$C:$C,MATCH(D$3,'OCRMS Risk Map'!$A:$A,0)),0)) -> 0 | E1: =IF(E$3="",0,IFERROR(INDEX('OCRMS Risk Map'!$C:$C,MATCH(E$3,'OCRMS Risk Map'!$A:$A,0)),0)) -> 0 | F1: =IF(F$3="",0,IFERROR(INDEX('OCRMS Risk Map'!$C:$C,MATCH(F$3,'OCRMS Risk Map'!$A:$A,0)),0)) -> 0 | G1: =IF(G$3="",0,IFERROR(INDEX('OCRMS Risk Map'!$C:$C,MATCH(G$3,'OCRMS Risk Map'!$A:$A,0)),0)) -> 0 | H1: =IF(H$3="",0,IFERROR(INDEX('OCRMS Risk Map'!$C:$C,MATCH(H$3,'OCRMS Risk Map'!$A:$A,0)),0)) -> 0 | I1: =IF(I$3="",0,IFERROR(INDEX('OCRMS Risk Map'!$C:$C,MATCH(I$3,'OCRMS Risk Map'!$A:$A,0)),0)) -> 0 | ... CH1: =IF(CH$3="",0,IFERROR(INDEX('OCRMS Risk Map'!$C:$C,MATCH(CH$3,'OCRMS Risk Map'!$A:$A,0)),0)) -> 0
A2: Select your pivot in your compliance system (the "Row Labels" header, every parameter column, the Grand Total row/column — everything) and paste it starting at cell A3, exactly as exported. Do not reshape it or skip rows. Rows 1-2 hold formulas — paste at A3, never A1. | B2: =IF(B$3="","",IFERROR(INDEX('OCRMS Risk Map'!$B:$B,MATCH(B$3,'OCRMS Risk Map'!$A:$A,0)),"")) | C2: =IF(C$3="","",IFERROR(INDEX('OCRMS Risk Map'!$B:$B,MATCH(C$3,'OCRMS Risk Map'!$A:$A,0)),"")) | D2: =IF(D$3="","",IFERROR(INDEX('OCRMS Risk Map'!$B:$B,MATCH(D$3,'OCRMS Risk Map'!$A:$A,0)),"")) | E2: =IF(E$3="","",IFERROR(INDEX('OCRMS Risk Map'!$B:$B,MATCH(E$3,'OCRMS Risk Map'!$A:$A,0)),"")) | F2: =IF(F$3="","",IFERROR(INDEX('OCRMS Risk Map'!$B:$B,MATCH(F$3,'OCRMS Risk Map'!$A:$A,0)),"")) | G2: =IF(G$3="","",IFERROR(INDEX('OCRMS Risk Map'!$B:$B,MATCH(G$3,'OCRMS Risk Map'!$A:$A,0)),"")) | H2: =IF(H$3="","",IFERROR(INDEX('OCRMS Risk Map'!$B:$B,MATCH(H$3,'OCRMS Risk Map'!$A:$A,0)),"")) | I2: =IF(I$3="","",IFERROR(INDEX('OCRMS Risk Map'!$B:$B,MATCH(I$3,'OCRMS Risk Map'!$A:$A,0)),"")) | ... CH2: =IF(CH$3="","",IFERROR(INDEX('OCRMS Risk Map'!$B:$B,MATCH(CH$3,'OCRMS Risk Map'!$A:$A,0)),""))
A3: Row Labels | CJ3: High-Risk Hit? (auto)
CJ4: =IF(OR($A4="",LOWER(TRIM($A4))="grand total"),"",IF(SUMPRODUCT(($B4:$CH4>0)*($B$2:$CH$2="H"))>0,1,0))
CJ5: =IF(OR($A5="",LOWER(TRIM($A5))="grand total"),"",IF(SUMPRODUCT(($B5:$CH5>0)*($B$2:$CH$2="H"))>0,1,0))
CJ6: =IF(OR($A6="",LOWER(TRIM($A6))="grand total"),"",IF(SUMPRODUCT(($B6:$CH6>0)*($B$2:$CH$2="H"))>0,1,0))
CJ7: =IF(OR($A7="",LOWER(TRIM($A7))="grand total"),"",IF(SUMPRODUCT(($B7:$CH7>0)*($B$2:$CH$2="H"))>0,1,0))
CJ8: =IF(OR($A8="",LOWER(TRIM($A8))="grand total"),"",IF(SUMPRODUCT(($B8:$CH8>0)*($B$2:$CH$2="H"))>0,1,0))
CJ9: =IF(OR($A9="",LOWER(TRIM($A9))="grand total"),"",IF(SUMPRODUCT(($B9:$CH9>0)*($B$2:$CH$2="H"))>0,1,0))
CJ10: =IF(OR($A10="",LOWER(TRIM($A10))="grand total"),"",IF(SUMPRODUCT(($B10:$CH10>0)*($B$2:$CH$2="H"))>0,1,0))
CJ11: =IF(OR($A11="",LOWER(TRIM($A11))="grand total"),"",IF(SUMPRODUCT(($B11:$CH11>0)*($B$2:$CH$2="H"))>0,1,0))
CJ12: =IF(OR($A12="",LOWER(TRIM($A12))="grand total"),"",IF(SUMPRODUCT(($B12:$CH12>0)*($B$2:$CH$2="H"))>0,1,0))
CJ13: =IF(OR($A13="",LOWER(TRIM($A13))="grand total"),"",IF(SUMPRODUCT(($B13:$CH13>0)*($B$2:$CH$2="H"))>0,1,0))
CJ14: =IF(OR($A14="",LOWER(TRIM($A14))="grand total"),"",IF(SUMPRODUCT(($B14:$CH14>0)*($B$2:$CH$2="H"))>0,1,0))
CJ15: =IF(OR($A15="",LOWER(TRIM($A15))="grand total"),"",IF(SUMPRODUCT(($B15:$CH15>0)*($B$2:$CH$2="H"))>0,1,0))
... CJ303: =IF(OR($A303="",LOWER(TRIM($A303))="grand total"),"",IF(SUMPRODUCT(($B303:$CH303>0)*($B$2:$CH$2="H"))>0,1,0))
A305: Hit? (auto) | B305: =IF(B1=0,0,IF(COUNTIF(B4:B303,">0")>0,1,0)) -> 0 | C305: =IF(C1=0,0,IF(COUNTIF(C4:C303,">0")>0,1,0)) -> 0 | D305: =IF(D1=0,0,IF(COUNTIF(D4:D303,">0")>0,1,0)) -> 0 | E305: =IF(E1=0,0,IF(COUNTIF(E4:E303,">0")>0,1,0)) -> 0 | F305: =IF(F1=0,0,IF(COUNTIF(F4:F303,">0")>0,1,0)) -> 0 | G305: =IF(G1=0,0,IF(COUNTIF(G4:G303,">0")>0,1,0)) -> 0 | H305: =IF(H1=0,0,IF(COUNTIF(H4:H303,">0")>0,1,0)) -> 0 | I305: =IF(I1=0,0,IF(COUNTIF(I4:I303,">0")>0,1,0)) -> 0 | ... CH305: =IF(CH1=0,0,IF(COUNTIF(CH4:CH303,">0")>0,1,0)) -> 0
A306: Weight Contributed (auto) | B306: =B305*B1 -> 0 | C306: =C305*C1 -> 0 | D306: =D305*D1 -> 0 | E306: =E305*E1 -> 0 | F306: =F305*F1 -> 0 | G306: =G305*G1 -> 0 | H306: =H305*H1 -> 0 | I306: =I305*I1 -> 0 | ... CH306: =CH305*CH1 -> 0
A309: OCRMS PART A / B SUMMARY
A310: Risk score obtained | B310: =SUM(B306:CH306) -> 0
A311: Total risk (denominator) | B311: 139
A312: Compliance % (A) | B312: =1-(B310/B311) -> 1
A313: Marks A (0-1) | B313: =MIN(1,MAX(0,ROUND(B312,2))) -> 1
A315: Total branches in Region | B315: =Calculator!$B$6 -> 55
A316: Branches with HIGH-risk violation | B316: =SUM(CJ4:CJ303) -> 0
A317: Compliance % (B) | B317: =1-(B316/B315) -> 1
A318: Marks B (0-1) | B318: =MIN(1,MAX(0,ROUND(B317,2))) -> 1

Sheet OCTMS Data
A1: OCTMS Data — paste your RAW OCTMS system export here, starting at cell A2 | AF1: Paste the export exactly as your system generates it — every column (TRACKER_ID, RISK, BRANCH_ALPHA, PARAMETER_VALUE, ... FINAL_STATUS_OF_PARAMETER, ...), every row, header included — starting at cell A2. No pivoting, no reshaping. Column order does not matter; the sheet finds BRANCH_ALPHA, PARAMETER_VALUE and FINAL_STATUS_OF_PARAMETER by their header text.
A2: BRANCH_ALPHA | AH2: Distinct non-complied branch? (auto)
AF3: Column lookup (auto — do not edit) | AH3: =IF($AG$4=0,0,IF($AG$6=0,0,IF(INDEX($A3:$AD3,$AG$4)="",0,IF(INDEX($A3:$AD3,$AG$6)<>"NON-COMPLIED",0,IF(COUNTIFS(INDEX($A$3:$AD$3,0,$AG$4),INDEX($A3:$AD3,$AG$4),INDEX($A$3:$AD$3,0,$AG$6),"NON-COMPLIED")=1,1,0))))) -> 0
AF4: BRANCH_ALPHA column # | AG4: =IFERROR(MATCH("BRANCH_ALPHA",$A$2:$AD$2,0),0) -> 1 | AH4: =IF($AG$4=0,0,IF($AG$6=0,0,IF(INDEX($A4:$AD4,$AG$4)="",0,IF(INDEX($A4:$AD4,$AG$6)<>"NON-COMPLIED",0,IF(COUNTIFS(INDEX($A$3:$AD$4,0,$AG$4),INDEX($A4:$AD4,$AG$4),INDEX($A$3:$AD$4,0,$AG$6),"NON-COMPLIED")=1,1,0))))) -> 0
AF5: PARAMETER_VALUE column # | AG5: =IFERROR(MATCH("PARAMETER_VALUE",$A$2:$AD$2,0),0) -> 0 | AH5: =IF($AG$4=0,0,IF($AG$6=0,0,IF(INDEX($A5:$AD5,$AG$4)="",0,IF(INDEX($A5:$AD5,$AG$6)<>"NON-COMPLIED",0,IF(COUNTIFS(INDEX($A$3:$AD$5,0,$AG$4),INDEX($A5:$AD5,$AG$4),INDEX($A$3:$AD$5,0,$AG$6),"NON-COMPLIED")=1,1,0))))) -> 0
AF6: FINAL_STATUS_OF_PARAMETER column # | AG6: =IFERROR(MATCH("FINAL_STATUS_OF_PARAMETER",$A$2:$AD$2,0),0) -> 0 | AH6: =IF($AG$4=0,0,IF($AG$6=0,0,IF(INDEX($A6:$AD6,$AG$4)="",0,IF(INDEX($A6:$AD6,$AG$6)<>"NON-COMPLIED",0,IF(COUNTIFS(INDEX($A$3:$AD$6,0,$AG$4),INDEX($A6:$AD6,$AG$4),INDEX($A$3:$AD$6,0,$AG$6),"NON-COMPLIED")=1,1,0))))) -> 0
AH7: =IF($AG$4=0,0,IF($AG$6=0,0,IF(INDEX($A7:$AD7,$AG$4)="",0,IF(INDEX($A7:$AD7,$AG$6)<>"NON-COMPLIED",0,IF(COUNTIFS(INDEX($A$3:$AD$7,0,$AG$4),INDEX($A7:$AD7,$AG$4),INDEX($A$3:$AD$7,0,$AG$6),"NON-COMPLIED")=1,1,0))))) -> 0
AH8: =IF($AG$4=0,0,IF($AG$6=0,0,IF(INDEX($A8:$AD8,$AG$4)="",0,IF(INDEX($A8:$AD8,$AG$6)<>"NON-COMPLIED",0,IF(COUNTIFS(INDEX($A$3:$AD$8,0,$AG$4),INDEX($A8:$AD8,$AG$4),INDEX($A$3:$AD$8,0,$AG$6),"NON-COMPLIED")=1,1,0))))) -> 0
AH9: =IF($AG$4=0,0,IF($AG$6=0,0,IF(INDEX($A9:$AD9,$AG$4)="",0,IF(INDEX($A9:$AD9,$AG$6)<>"NON-COMPLIED",0,IF(COUNTIFS(INDEX($A$3:$AD$9,0,$AG$4),INDEX($A9:$AD9,$AG$4),INDEX($A$3:$AD$9,0,$AG$6),"NON-COMPLIED")=1,1,0))))) -> 0
AH10: =IF($AG$4=0,0,IF($AG$6=0,0,IF(INDEX($A10:$AD10,$AG$4)="",0,IF(INDEX($A10:$AD10,$AG$6)<>"NON-COMPLIED",0,IF(COUNTIFS(INDEX($A$3:$AD$10,0,$AG$4),INDEX($A10:$AD10,$AG$4),INDEX($A$3:$AD$10,0,$AG$6),"NON-COMPLIED")=1,1,0))))) -> 0
AH11: =IF($AG$4=0,0,IF($AG$6=0,0,IF(INDEX($A11:$AD11,$AG$4)="",0,IF(INDEX($A11:$AD11,$AG$6)<>"NON-COMPLIED",0,IF(COUNTIFS(INDEX($A$3:$AD$11,0,$AG$4),INDEX($A11:$AD11,$AG$4),INDEX($A$3:$AD$11,0,$AG$6),"NON-COMPLIED")=1,1,0))))) -> 0
AH12: =IF($AG$4=0,0,IF($AG$6=0,0,IF(INDEX($A12:$AD12,$AG$4)="",0,IF(INDEX($A12:$AD12,$AG$6)<>"NON-COMPLIED",0,IF(COUNTIFS(INDEX($A$3:$AD$12,0,$AG$4),INDEX($A12:$AD12,$AG$4),INDEX($A$3:$AD$12,0,$AG$6),"NON-COMPLIED")=1,1,0))))) -> 0
AH13: =IF($AG$4=0,0,IF($AG$6=0,0,IF(INDEX($A13:$AD13,$AG$4)="",0,IF(INDEX($A13:$AD13,$AG$6)<>"NON-COMPLIED",0,IF(COUNTIFS(INDEX($A$3:$AD$13,0,$AG$4),INDEX($A13:$AD13,$AG$4),INDEX($A$3:$AD$13,0,$AG$6),"NON-COMPLIED")=1,1,0))))) -> 0
AH14: =IF($AG$4=0,0,IF($AG$6=0,0,IF(INDEX($A14:$AD14,$AG$4)="",0,IF(INDEX($A14:$AD14,$AG$6)<>"NON-COMPLIED",0,IF(COUNTIFS(INDEX($A$3:$AD$14,0,$AG$4),INDEX($A14:$AD14,$AG$4),INDEX($A$3:$AD$14,0,$AG$6),"NON-COMPLIED")=1,1,0))))) -> 0
AH15: =IF($AG$4=0,0,IF($AG$6=0,0,IF(INDEX($A15:$AD15,$AG$4)="",0,IF(INDEX($A15:$AD15,$AG$6)<>"NON-COMPLIED",0,IF(COUNTIFS(INDEX($A$3:$AD$15,0,$AG$4),INDEX($A15:$AD15,$AG$4),INDEX($A$3:$AD$15,0,$AG$6),"NON-COMPLIED")=1,1,0))))) -> 0
AH16: =IF($AG$4=0,0,IF($AG$6=0,0,IF(INDEX($A16:$AD16,$AG$4)="",0,IF(INDEX($A16:$AD16,$AG$6)<>"NON-COMPLIED",0,IF(COUNTIFS(INDEX($A$3:$AD$16,0,$AG$4),INDEX($A16:$AD16,$AG$4),INDEX($A$3:$AD$16,0,$AG$6),"NON-COMPLIED")=1,1,0))))) -> 0
AH17: =IF($AG$4=0,0,IF($AG$6=0,0,IF(INDEX($A17:$AD17,$AG$4)="",0,IF(INDEX($A17:$AD17,$AG$6)<>"NON-COMPLIED",0,IF(COUNTIFS(INDEX($A$3:$AD$17,0,$AG$4),INDEX($A17:$AD17,$AG$4),INDEX($A$3:$AD$17,0,$AG$6),"NON-COMPLIED")=1,1,0))))) -> 0
AH18: =IF($AG$4=0,0,IF($AG$6=0,0,IF(INDEX($A18:$AD18,$AG$4)="",0,IF(INDEX($A18:$AD18,$AG$6)<>"NON-COMPLIED",0,IF(COUNTIFS(INDEX($A$3:$AD$18,0,$AG$4),INDEX($A18:$AD18,$AG$4),INDEX($A$3:$AD$18,0,$AG$6),"NON-COMPLIED")=1,1,0))))) -> 0
AH19: =IF($AG$4=0,0,IF($AG$6=0,0,IF(INDEX($A19:$AD19,$AG$4)="",0,IF(INDEX($A19:$AD19,$AG$6)<>"NON-COMPLIED",0,IF(COUNTIFS(INDEX($A$3:$AD$19,0,$AG$4),INDEX($A19:$AD19,$AG$4),INDEX($A$3:$AD$19,0,$AG$6),"NON-COMPLIED")=1,1,0))))) -> 0
AH20: =IF($AG$4=0,0,IF($AG$6=0,0,IF(INDEX($A20:$AD20,$AG$4)="",0,IF(INDEX($A20:$AD20,$AG$6)<>"NON-COMPLIED",0,IF(COUNTIFS(INDEX($A$3:$AD$20,0,$AG$4),INDEX($A20:$AD20,$AG$4),INDEX($A$3:$AD$20,0,$AG$6),"NON-COMPLIED")=1,1,0))))) -> 0
AH21: =IF($AG$4=0,0,IF($AG$6=0,0,IF(INDEX($A21:$AD21,$AG$4)="",0,IF(INDEX($A21:$AD21,$AG$6)<>"NON-COMPLIED",0,IF(COUNTIFS(INDEX($A$3:$AD$21,0,$AG$4),INDEX($A21:$AD21,$AG$4),INDEX($A$3:$AD$21,0,$AG$6),"NON-COMPLIED")=1,1,0))))) -> 0
AH22: =IF($AG$4=0,0,IF($AG$6=0,0,IF(INDEX($A22:$AD22,$AG$4)="",0,IF(INDEX($A22:$AD22,$AG$6)<>"NON-COMPLIED",0,IF(COUNTIFS(INDEX($A$3:$AD$22,0,$AG$4),INDEX($A22:$AD22,$AG$4),INDEX($A$3:$AD$22,0,$AG$6),"NON-COMPLIED")=1,1,0))))) -> 0
AH23: =IF($AG$4=0,0,IF($AG$6=0,0,IF(INDEX($A23:$AD23,$AG$4)="",0,IF(INDEX($A23:$AD23,$AG$6)<>"NON-COMPLIED",0,IF(COUNTIFS(INDEX($A$3:$AD$23,0,$AG$4),INDEX($A23:$AD23,$AG$4),INDEX($A$3:$AD$23,0,$AG$6),"NON-COMPLIED")=1,1,0))))) -> 0
AH24: =IF($AG$4=0,0,IF($AG$6=0,0,IF(INDEX($A24:$AD24,$AG$4)="",0,IF(INDEX($A24:$AD24,$AG$6)<>"NON-COMPLIED",0,IF(COUNTIFS(INDEX($A$3:$AD$24,0,$AG$4),INDEX($A24:$AD24,$AG$4),INDEX($A$3:$AD$24,0,$AG$6),"NON-COMPLIED")=1,1,0))))) -> 0
AH25: =IF($AG$4=0,0,IF($AG$6=0,0,IF(INDEX($A25:$AD25,$AG$4)="",0,IF(INDEX($A25:$AD25,$AG$6)<>"NON-COMPLIED",0,IF(COUNTIFS(INDEX($A$3:$AD$25,0,$AG$4),INDEX($A25:$AD25,$AG$4),INDEX($A$3:$AD$25,0,$AG$6),"NON-COMPLIED")=1,1,0))))) -> 0
AH26: =IF($AG$4=0,0,IF($AG$6=0,0,IF(INDEX($A26:$AD26,$AG$4)="",0,IF(INDEX($A26:$AD26,$AG$6)<>"NON-COMPLIED",0,IF(COUNTIFS(INDEX($A$3:$AD$26,0,$AG$4),INDEX($A26:$AD26,$AG$4),INDEX($A$3:$AD$26,0,$AG$6),"NON-COMPLIED")=1,1,0))))) -> 0
AH27: =IF($AG$4=0,0,IF($AG$6=0,0,IF(INDEX($A27:$AD27,$AG$4)="",0,IF(INDEX($A27:$AD27,$AG$6)<>"NON-COMPLIED",0,IF(COUNTIFS(INDEX($A$3:$AD$27,0,$AG$4),INDEX($A27:$AD27,$AG$4),INDEX($A$3:$AD$27,0,$AG$6),"NON-COMPLIED")=1,1,0))))) -> 0
AH28: =IF($AG$4=0,0,IF($AG$6=0,0,IF(INDEX($A28:$AD28,$AG$4)="",0,IF(INDEX($A28:$AD28,$AG$6)<>"NON-COMPLIED",0,IF(COUNTIFS(INDEX($A$3:$AD$28,0,$AG$4),INDEX($A28:$AD28,$AG$4),INDEX($A$3:$AD$28,0,$AG$6),"NON-COMPLIED")=1,1,0))))) -> 0
AH29: =IF($AG$4=0,0,IF($AG$6=0,0,IF(INDEX($A29:$AD29,$AG$4)="",0,IF(INDEX($A29:$AD29,$AG$6)<>"NON-COMPLIED",0,IF(COUNTIFS(INDEX($A$3:$AD$29,0,$AG$4),INDEX($A29:$AD29,$AG$4),INDEX($A$3:$AD$29,0,$AG$6),"NON-COMPLIED")=1,1,0))))) -> 0
AH30: =IF($AG$4=0,0,IF($AG$6=0,0,IF(INDEX($A30:$AD30,$AG$4)="",0,IF(INDEX($A30:$AD30,$AG$6)<>"NON-COMPLIED",0,IF(COUNTIFS(INDEX($A$3:$AD$30,0,$AG$4),INDEX($A30:$AD30,$AG$4),INDEX($A$3:$AD$30,0,$AG$6),"NON-COMPLIED")=1,1,0))))) -> 0
AH31: =IF($AG$4=0,0,IF($AG$6=0,0,IF(INDEX($A31:$AD31,$AG$4)="",0,IF(INDEX($A31:$AD31,$AG$6)<>"NON-COMPLIED",0,IF(COUNTIFS(INDEX($A$3:$AD$31,0,$AG$4),INDEX($A31:$AD31,$AG$4),INDEX($A$3:$AD$31,0,$AG$6),"NON-COMPLIED")=1,1,0))))) -> 0
AH32: =IF($AG$4=0,0,IF($AG$6=0,0,IF(INDEX($A32:$AD32,$AG$4)="",0,IF(INDEX($A32:$AD32,$AG$6)<>"NON-COMPLIED",0,IF(COUNTIFS(INDEX($A$3:$AD$32,0,$AG$4),INDEX($A32:$AD32,$AG$4),INDEX($A$3:$AD$32,0,$AG$6),"NON-COMPLIED")=1,1,0))))) -> 0
AH33: =IF($AG$4=0,0,IF($AG$6=0,0,IF(INDEX($A33:$AD33,$AG$4)="",0,IF(INDEX($A33:$AD33,$AG$6)<>"NON-COMPLIED",0,IF(COUNTIFS(INDEX($A$3:$AD$33,0,$AG$4),INDEX($A33:$AD33,$AG$4),INDEX($A$3:$AD$33,0,$AG$6),"NON-COMPLIED")=1,1,0))))) -> 0
AH34: =IF($AG$4=0,0,IF($AG$6=0,0,IF(INDEX($A34:$AD34,$AG$4)="",0,IF(INDEX($A34:$AD34,$AG$6)<>"NON-COMPLIED",0,IF(COUNTIFS(INDEX($A$3:$AD$34,0,$AG$4),INDEX($A34:$AD34,$AG$4),INDEX($A$3:$AD$34,0,$AG$6),"NON-COMPLIED")=1,1,0))))) -> 0
AH35: =IF($AG$4=0,0,IF($AG$6=0,0,IF(INDEX($A35:$AD35,$AG$4)="",0,IF(INDEX($A35:$AD35,$AG$6)<>"NON-COMPLIED",0,IF(COUNTIFS(INDEX($A$3:$AD$35,0,$AG$4),INDEX($A35:$AD35,$AG$4),INDEX($A$3:$AD$35,0,$AG$6),"NON-COMPLIED")=1,1,0))))) -> 0
AH36: =IF($AG$4=0,0,IF($AG$6=0,0,IF(INDEX($A36:$AD36,$AG$4)="",0,IF(INDEX($A36:$AD36,$AG$6)<>"NON-COMPLIED",0,IF(COUNTIFS(INDEX($A$3:$AD$36,0,$AG$4),INDEX($A36:$AD36,$AG$4),INDEX($A$3:$AD$36,0,$AG$6),"NON-COMPLIED")=1,1,0))))) -> 0
AH37: =IF($AG$4=0,0,IF($AG$6=0,0,IF(INDEX($A37:$AD37,$AG$4)="",0,IF(INDEX($A37:$AD37,$AG$6)<>"NON-COMPLIED",0,IF(COUNTIFS(INDEX($A$3:$AD$37,0,$AG$4),INDEX($A37:$AD37,$AG$4),INDEX($A$3:$AD$37,0,$AG$6),"NON-COMPLIED")=1,1,0))))) -> 0
AH38: =IF($AG$4=0,0,IF($AG$6=0,0,IF(INDEX($A38:$AD38,$AG$4)="",0,IF(INDEX($A38:$AD38,$AG$6)<>"NON-COMPLIED",0,IF(COUNTIFS(INDEX($A$3:$AD$38,0,$AG$4),INDEX($A38:$AD38,$AG$4),INDEX($A$3:$AD$38,0,$AG$6),"NON-COMPLIED")=1,1,0))))) -> 0
AH39: =IF($AG$4=0,0,IF($AG$6=0,0,IF(INDEX($A39:$AD39,$AG$4)="",0,IF(INDEX($A39:$AD39,$AG$6)<>"NON-COMPLIED",0,IF(COUNTIFS(INDEX($A$3:$AD$39,0,$AG$4),INDEX($A39:$AD39,$AG$4),INDEX($A$3:$AD$39,0,$AG$6),"NON-COMPLIED")=1,1,0))))) -> 0
AH40: =IF($AG$4=0,0,IF($AG$6=0,0,IF(INDEX($A40:$AD40,$AG$4)="",0,IF(INDEX($A40:$AD40,$AG$6)<>"NON-COMPLIED",0,IF(COUNTIFS(INDEX($A$3:$AD$40,0,$AG$4),INDEX($A40:$AD40,$AG$4),INDEX($A$3:$AD$40,0,$AG$6),"NON-COMPLIED")=1,1,0))))) -> 0
...
